[2017-04-02 21:42:49 +0800] [3497] [INFO] Starting gunicorn 19.3.0
[2017-04-02 21:42:49 +0800] [3497] [INFO] Listening at: http://127.0.0.1:8000 (3497)
[2017-04-02 21:42:49 +0800] [3497] [INFO] Using worker: sync
[2017-04-02 21:42:49 +0800] [3500] [INFO] Booting worker with pid: 3500
[2017-04-02 21:43:02 +0800] [3500] [ERROR] Error handling request
Traceback (most recent call last):
  File "/Users/lhq/anaconda2/lib/python2.7/site-packages/gunicorn/workers/sync.py", line 130, in handle
    self.handle_request(listener, req, client, addr)
  File "/Users/lhq/anaconda2/lib/python2.7/site-packages/gunicorn/workers/sync.py", line 171, in handle_request
    respiter = self.wsgi(environ, resp.start_response)
  File "/Users/lhq/anaconda2/lib/python2.7/site-packages/flask/app.py", line 1836, in __call__
    return self.wsgi_app(environ, start_response)
  File "/Users/lhq/anaconda2/lib/python2.7/site-packages/flask/app.py", line 1820, in wsgi_app
    response = self.make_response(self.handle_exception(e))
  File "/Users/lhq/anaconda2/lib/python2.7/site-packages/flask/app.py", line 1403, in handle_exception
    reraise(exc_type, exc_value, tb)
  File "/Users/lhq/anaconda2/lib/python2.7/site-packages/flask/app.py", line 1817, in wsgi_app
    response = self.full_dispatch_request()
  File "/Users/lhq/anaconda2/lib/python2.7/site-packages/flask/app.py", line 1477, in full_dispatch_request
    rv = self.handle_user_exception(e)
  File "/Users/lhq/anaconda2/lib/python2.7/site-packages/flask/app.py", line 1381, in handle_user_exception
    reraise(exc_type, exc_value, tb)
  File "/Users/lhq/anaconda2/lib/python2.7/site-packages/flask/app.py", line 1475, in full_dispatch_request
    rv = self.dispatch_request()
  File "/Users/lhq/anaconda2/lib/python2.7/site-packages/flask/app.py", line 1461, in dispatch_request
    return self.view_functions[rule.endpoint](**req.view_args)
  File "/Users/lhq/Workspace/im2txt_api/im2txt/run_inference.py", line 148, in upload
    file.save(path)
  File "/Users/lhq/anaconda2/lib/python2.7/site-packages/werkzeug/datastructures.py", line 2653, in save
    dst = open(dst, 'wb')
IOError: [Errno 13] Permission denied: '/tmp/cef82dd8070edcfb73d28c27df4312bd.jpg'
[2017-04-02 21:43:32 +0800] [3497] [CRITICAL] WORKER TIMEOUT (pid:3500)
[2017-04-02 21:43:32 +0800] [3500] [INFO] Worker exiting (pid: 3500)
[2017-04-02 21:43:33 +0800] [3518] [INFO] Booting worker with pid: 3518
[2017-04-02 21:43:49 +0800] [3518] [ERROR] Error handling request
Traceback (most recent call last):
  File "/Users/lhq/anaconda2/lib/python2.7/site-packages/gunicorn/workers/sync.py", line 130, in handle
    self.handle_request(listener, req, client, addr)
  File "/Users/lhq/anaconda2/lib/python2.7/site-packages/gunicorn/workers/sync.py", line 171, in handle_request
    respiter = self.wsgi(environ, resp.start_response)
  File "/Users/lhq/anaconda2/lib/python2.7/site-packages/flask/app.py", line 1836, in __call__
    return self.wsgi_app(environ, start_response)
  File "/Users/lhq/anaconda2/lib/python2.7/site-packages/flask/app.py", line 1820, in wsgi_app
    response = self.make_response(self.handle_exception(e))
  File "/Users/lhq/anaconda2/lib/python2.7/site-packages/flask/app.py", line 1403, in handle_exception
    reraise(exc_type, exc_value, tb)
  File "/Users/lhq/anaconda2/lib/python2.7/site-packages/flask/app.py", line 1817, in wsgi_app
    response = self.full_dispatch_request()
  File "/Users/lhq/anaconda2/lib/python2.7/site-packages/flask/app.py", line 1477, in full_dispatch_request
    rv = self.handle_user_exception(e)
  File "/Users/lhq/anaconda2/lib/python2.7/site-packages/flask/app.py", line 1381, in handle_user_exception
    reraise(exc_type, exc_value, tb)
  File "/Users/lhq/anaconda2/lib/python2.7/site-packages/flask/app.py", line 1475, in full_dispatch_request
    rv = self.dispatch_request()
  File "/Users/lhq/anaconda2/lib/python2.7/site-packages/flask/app.py", line 1461, in dispatch_request
    return self.view_functions[rule.endpoint](**req.view_args)
  File "/Users/lhq/Workspace/im2txt_api/im2txt/run_inference.py", line 148, in upload
    file.save(path)
  File "/Users/lhq/anaconda2/lib/python2.7/site-packages/werkzeug/datastructures.py", line 2653, in save
    dst = open(dst, 'wb')
IOError: [Errno 13] Permission denied: '/tmp/cef82dd8070edcfb73d28c27df4312bd.jpg'
[2017-04-02 21:44:00 +0800] [3497] [INFO] Handling signal: int
[2017-04-02 21:44:00 +0800] [3518] [INFO] Worker exiting (pid: 3518)
[2017-04-02 21:44:00 +0800] [3497] [INFO] Shutting down: Master
[2017-04-02 22:22:28 +0800] [4043] [INFO] Starting gunicorn 19.3.0
[2017-04-02 22:22:28 +0800] [4043] [INFO] Listening at: http://127.0.0.1:8000 (4043)
[2017-04-02 22:22:28 +0800] [4043] [INFO] Using worker: sync
[2017-04-02 22:22:28 +0800] [4046] [INFO] Booting worker with pid: 4046
[2017-04-02 22:23:10 +0800] [4043] [INFO] Handling signal: int
[2017-04-02 22:23:11 +0800] [4046] [INFO] Worker exiting (pid: 4046)
[2017-04-02 22:23:11 +0800] [4043] [INFO] Shutting down: Master
[2017-04-02 22:23:13 +0800] [4059] [INFO] Starting gunicorn 19.3.0
[2017-04-02 22:23:13 +0800] [4059] [INFO] Listening at: http://127.0.0.1:8000 (4059)
[2017-04-02 22:23:13 +0800] [4059] [INFO] Using worker: sync
[2017-04-02 22:23:13 +0800] [4062] [INFO] Booting worker with pid: 4062
[2017-04-02 22:23:37 +0800] [4059] [INFO] Handling signal: int
[2017-04-02 22:23:37 +0800] [4062] [INFO] Worker exiting (pid: 4062)
[2017-04-02 22:23:38 +0800] [4059] [INFO] Shutting down: Master
[2017-04-02 22:25:16 +0800] [4076] [INFO] Starting gunicorn 19.3.0
[2017-04-02 22:25:16 +0800] [4076] [INFO] Listening at: http://127.0.0.1:8000 (4076)
[2017-04-02 22:25:16 +0800] [4076] [INFO] Using worker: sync
[2017-04-02 22:25:16 +0800] [4079] [INFO] Booting worker with pid: 4079
[2017-04-02 22:26:22 +0800] [4076] [INFO] Handling signal: int
[2017-04-02 22:26:22 +0800] [4079] [INFO] Worker exiting (pid: 4079)
[2017-04-02 22:26:23 +0800] [4076] [INFO] Shutting down: Master
[2017-04-02 22:26:29 +0800] [4092] [INFO] Starting gunicorn 19.3.0
[2017-04-02 22:26:29 +0800] [4092] [INFO] Listening at: http://127.0.0.1:8000 (4092)
[2017-04-02 22:26:29 +0800] [4092] [INFO] Using worker: sync
[2017-04-02 22:26:29 +0800] [4095] [INFO] Booting worker with pid: 4095
[2017-04-02 22:26:36 +0800] [4092] [INFO] Handling signal: int
[2017-04-02 22:26:36 +0800] [4095] [INFO] Worker exiting (pid: 4095)
[2017-04-02 22:26:36 +0800] [4092] [INFO] Shutting down: Master
[2017-04-02 22:27:50 +0800] [4148] [INFO] Starting gunicorn 19.3.0
[2017-04-02 22:27:50 +0800] [4148] [INFO] Listening at: http://127.0.0.1:8000 (4148)
[2017-04-02 22:27:50 +0800] [4148] [INFO] Using worker: sync
[2017-04-02 22:27:50 +0800] [4151] [INFO] Booting worker with pid: 4151
[2017-04-02 22:29:06 +0800] [4148] [INFO] Handling signal: int
[2017-04-02 22:29:06 +0800] [4151] [INFO] Worker exiting (pid: 4151)
[2017-04-02 22:29:06 +0800] [4148] [INFO] Shutting down: Master
[2017-04-02 22:31:03 +0800] [4265] [INFO] Starting gunicorn 19.3.0
[2017-04-02 22:31:03 +0800] [4265] [INFO] Listening at: http://127.0.0.1:8000 (4265)
[2017-04-02 22:31:03 +0800] [4265] [INFO] Using worker: sync
[2017-04-02 22:31:03 +0800] [4268] [INFO] Booting worker with pid: 4268
[2017-04-02 22:31:03 +0800] [4268] [ERROR] Exception in worker process:
Traceback (most recent call last):
  File "/Users/lhq/anaconda2/lib/python2.7/site-packages/gunicorn/arbiter.py", line 507, in spawn_worker
    worker.init_process()
  File "/Users/lhq/anaconda2/lib/python2.7/site-packages/gunicorn/workers/base.py", line 118, in init_process
    self.wsgi = self.app.wsgi()
  File "/Users/lhq/anaconda2/lib/python2.7/site-packages/gunicorn/app/base.py", line 67, in wsgi
    self.callable = self.load()
  File "/Users/lhq/anaconda2/lib/python2.7/site-packages/gunicorn/app/wsgiapp.py", line 65, in load
    return self.load_wsgiapp()
  File "/Users/lhq/anaconda2/lib/python2.7/site-packages/gunicorn/app/wsgiapp.py", line 52, in load_wsgiapp
    return util.import_app(self.app_uri)
  File "/Users/lhq/anaconda2/lib/python2.7/site-packages/gunicorn/util.py", line 355, in import_app
    __import__(module)
ImportError: No module named run_inferencapp
Traceback (most recent call last):
  File "/Users/lhq/anaconda2/lib/python2.7/site-packages/gunicorn/arbiter.py", line 507, in spawn_worker
    worker.init_process()
  File "/Users/lhq/anaconda2/lib/python2.7/site-packages/gunicorn/workers/base.py", line 118, in init_process
    self.wsgi = self.app.wsgi()
  File "/Users/lhq/anaconda2/lib/python2.7/site-packages/gunicorn/app/base.py", line 67, in wsgi
    self.callable = self.load()
  File "/Users/lhq/anaconda2/lib/python2.7/site-packages/gunicorn/app/wsgiapp.py", line 65, in load
    return self.load_wsgiapp()
  File "/Users/lhq/anaconda2/lib/python2.7/site-packages/gunicorn/app/wsgiapp.py", line 52, in load_wsgiapp
    return util.import_app(self.app_uri)
  File "/Users/lhq/anaconda2/lib/python2.7/site-packages/gunicorn/util.py", line 355, in import_app
    __import__(module)
ImportError: No module named run_inferencapp
[2017-04-02 22:31:03 +0800] [4268] [INFO] Worker exiting (pid: 4268)
[2017-04-02 22:31:13 +0800] [4270] [INFO] Starting gunicorn 19.3.0
[2017-04-02 22:31:13 +0800] [4270] [INFO] Listening at: http://127.0.0.1:8000 (4270)
[2017-04-02 22:31:13 +0800] [4270] [INFO] Using worker: sync
[2017-04-02 22:31:13 +0800] [4273] [INFO] Booting worker with pid: 4273
[2017-04-02 22:31:13 +0800] [4273] [ERROR] Exception in worker process:
Traceback (most recent call last):
  File "/Users/lhq/anaconda2/lib/python2.7/site-packages/gunicorn/arbiter.py", line 507, in spawn_worker
    worker.init_process()
  File "/Users/lhq/anaconda2/lib/python2.7/site-packages/gunicorn/workers/base.py", line 118, in init_process
    self.wsgi = self.app.wsgi()
  File "/Users/lhq/anaconda2/lib/python2.7/site-packages/gunicorn/app/base.py", line 67, in wsgi
    self.callable = self.load()
  File "/Users/lhq/anaconda2/lib/python2.7/site-packages/gunicorn/app/wsgiapp.py", line 65, in load
    return self.load_wsgiapp()
  File "/Users/lhq/anaconda2/lib/python2.7/site-packages/gunicorn/app/wsgiapp.py", line 52, in load_wsgiapp
    return util.import_app(self.app_uri)
  File "/Users/lhq/anaconda2/lib/python2.7/site-packages/gunicorn/util.py", line 355, in import_app
    __import__(module)
ImportError: No module named run_inferencapp
Traceback (most recent call last):
  File "/Users/lhq/anaconda2/lib/python2.7/site-packages/gunicorn/arbiter.py", line 507, in spawn_worker
    worker.init_process()
  File "/Users/lhq/anaconda2/lib/python2.7/site-packages/gunicorn/workers/base.py", line 118, in init_process
    self.wsgi = self.app.wsgi()
  File "/Users/lhq/anaconda2/lib/python2.7/site-packages/gunicorn/app/base.py", line 67, in wsgi
    self.callable = self.load()
  File "/Users/lhq/anaconda2/lib/python2.7/site-packages/gunicorn/app/wsgiapp.py", line 65, in load
    return self.load_wsgiapp()
  File "/Users/lhq/anaconda2/lib/python2.7/site-packages/gunicorn/app/wsgiapp.py", line 52, in load_wsgiapp
    return util.import_app(self.app_uri)
  File "/Users/lhq/anaconda2/lib/python2.7/site-packages/gunicorn/util.py", line 355, in import_app
    __import__(module)
ImportError: No module named run_inferencapp
[2017-04-02 22:31:13 +0800] [4273] [INFO] Worker exiting (pid: 4273)
[2017-04-02 22:31:46 +0800] [4274] [INFO] Starting gunicorn 19.3.0
[2017-04-02 22:31:46 +0800] [4274] [INFO] Listening at: http://127.0.0.1:8000 (4274)
[2017-04-02 22:31:46 +0800] [4274] [INFO] Using worker: sync
[2017-04-02 22:31:46 +0800] [4277] [INFO] Booting worker with pid: 4277
[2017-04-02 22:31:47 +0800] [4277] [ERROR] Exception in worker process:
Traceback (most recent call last):
  File "/Users/lhq/anaconda2/lib/python2.7/site-packages/gunicorn/arbiter.py", line 507, in spawn_worker
    worker.init_process()
  File "/Users/lhq/anaconda2/lib/python2.7/site-packages/gunicorn/workers/base.py", line 118, in init_process
    self.wsgi = self.app.wsgi()
  File "/Users/lhq/anaconda2/lib/python2.7/site-packages/gunicorn/app/base.py", line 67, in wsgi
    self.callable = self.load()
  File "/Users/lhq/anaconda2/lib/python2.7/site-packages/gunicorn/app/wsgiapp.py", line 65, in load
    return self.load_wsgiapp()
  File "/Users/lhq/anaconda2/lib/python2.7/site-packages/gunicorn/app/wsgiapp.py", line 52, in load_wsgiapp
    return util.import_app(self.app_uri)
  File "/Users/lhq/anaconda2/lib/python2.7/site-packages/gunicorn/util.py", line 355, in import_app
    __import__(module)
ImportError: No module named run_inferencapp
Traceback (most recent call last):
  File "/Users/lhq/anaconda2/lib/python2.7/site-packages/gunicorn/arbiter.py", line 507, in spawn_worker
    worker.init_process()
  File "/Users/lhq/anaconda2/lib/python2.7/site-packages/gunicorn/workers/base.py", line 118, in init_process
    self.wsgi = self.app.wsgi()
  File "/Users/lhq/anaconda2/lib/python2.7/site-packages/gunicorn/app/base.py", line 67, in wsgi
    self.callable = self.load()
  File "/Users/lhq/anaconda2/lib/python2.7/site-packages/gunicorn/app/wsgiapp.py", line 65, in load
    return self.load_wsgiapp()
  File "/Users/lhq/anaconda2/lib/python2.7/site-packages/gunicorn/app/wsgiapp.py", line 52, in load_wsgiapp
    return util.import_app(self.app_uri)
  File "/Users/lhq/anaconda2/lib/python2.7/site-packages/gunicorn/util.py", line 355, in import_app
    __import__(module)
ImportError: No module named run_inferencapp
[2017-04-02 22:31:47 +0800] [4277] [INFO] Worker exiting (pid: 4277)
[2017-04-02 22:32:04 +0800] [4283] [INFO] Starting gunicorn 19.3.0
[2017-04-02 22:32:04 +0800] [4283] [INFO] Listening at: http://127.0.0.1:8000 (4283)
[2017-04-02 22:32:04 +0800] [4283] [INFO] Using worker: sync
[2017-04-02 22:32:04 +0800] [4286] [INFO] Booting worker with pid: 4286
[2017-04-02 22:32:04 +0800] [4286] [ERROR] Exception in worker process:
Traceback (most recent call last):
  File "/Users/lhq/anaconda2/lib/python2.7/site-packages/gunicorn/arbiter.py", line 507, in spawn_worker
    worker.init_process()
  File "/Users/lhq/anaconda2/lib/python2.7/site-packages/gunicorn/workers/base.py", line 118, in init_process
    self.wsgi = self.app.wsgi()
  File "/Users/lhq/anaconda2/lib/python2.7/site-packages/gunicorn/app/base.py", line 67, in wsgi
    self.callable = self.load()
  File "/Users/lhq/anaconda2/lib/python2.7/site-packages/gunicorn/app/wsgiapp.py", line 65, in load
    return self.load_wsgiapp()
  File "/Users/lhq/anaconda2/lib/python2.7/site-packages/gunicorn/app/wsgiapp.py", line 52, in load_wsgiapp
    return util.import_app(self.app_uri)
  File "/Users/lhq/anaconda2/lib/python2.7/site-packages/gunicorn/util.py", line 355, in import_app
    __import__(module)
ImportError: No module named run_inferencapp
Traceback (most recent call last):
  File "/Users/lhq/anaconda2/lib/python2.7/site-packages/gunicorn/arbiter.py", line 507, in spawn_worker
    worker.init_process()
  File "/Users/lhq/anaconda2/lib/python2.7/site-packages/gunicorn/workers/base.py", line 118, in init_process
    self.wsgi = self.app.wsgi()
  File "/Users/lhq/anaconda2/lib/python2.7/site-packages/gunicorn/app/base.py", line 67, in wsgi
    self.callable = self.load()
  File "/Users/lhq/anaconda2/lib/python2.7/site-packages/gunicorn/app/wsgiapp.py", line 65, in load
    return self.load_wsgiapp()
  File "/Users/lhq/anaconda2/lib/python2.7/site-packages/gunicorn/app/wsgiapp.py", line 52, in load_wsgiapp
    return util.import_app(self.app_uri)
  File "/Users/lhq/anaconda2/lib/python2.7/site-packages/gunicorn/util.py", line 355, in import_app
    __import__(module)
ImportError: No module named run_inferencapp
[2017-04-02 22:32:04 +0800] [4286] [INFO] Worker exiting (pid: 4286)
[2017-04-02 22:32:04 +0800] [4283] [INFO] Shutting down: Master
[2017-04-02 22:32:04 +0800] [4283] [INFO] Reason: Worker failed to boot.
[2017-04-02 22:33:21 +0800] [4301] [INFO] Starting gunicorn 19.3.0
[2017-04-02 22:33:21 +0800] [4301] [INFO] Listening at: http://127.0.0.1:8000 (4301)
[2017-04-02 22:33:21 +0800] [4301] [INFO] Using worker: sync
[2017-04-02 22:33:21 +0800] [4304] [INFO] Booting worker with pid: 4304
[2017-04-02 22:33:21 +0800] [4304] [ERROR] Exception in worker process:
Traceback (most recent call last):
  File "/Users/lhq/anaconda2/lib/python2.7/site-packages/gunicorn/arbiter.py", line 507, in spawn_worker
    worker.init_process()
  File "/Users/lhq/anaconda2/lib/python2.7/site-packages/gunicorn/workers/base.py", line 118, in init_process
    self.wsgi = self.app.wsgi()
  File "/Users/lhq/anaconda2/lib/python2.7/site-packages/gunicorn/app/base.py", line 67, in wsgi
    self.callable = self.load()
  File "/Users/lhq/anaconda2/lib/python2.7/site-packages/gunicorn/app/wsgiapp.py", line 65, in load
    return self.load_wsgiapp()
  File "/Users/lhq/anaconda2/lib/python2.7/site-packages/gunicorn/app/wsgiapp.py", line 52, in load_wsgiapp
    return util.import_app(self.app_uri)
  File "/Users/lhq/anaconda2/lib/python2.7/site-packages/gunicorn/util.py", line 355, in import_app
    __import__(module)
ImportError: No module named run_inferencapp
Traceback (most recent call last):
  File "/Users/lhq/anaconda2/lib/python2.7/site-packages/gunicorn/arbiter.py", line 507, in spawn_worker
    worker.init_process()
  File "/Users/lhq/anaconda2/lib/python2.7/site-packages/gunicorn/workers/base.py", line 118, in init_process
    self.wsgi = self.app.wsgi()
  File "/Users/lhq/anaconda2/lib/python2.7/site-packages/gunicorn/app/base.py", line 67, in wsgi
    self.callable = self.load()
  File "/Users/lhq/anaconda2/lib/python2.7/site-packages/gunicorn/app/wsgiapp.py", line 65, in load
    return self.load_wsgiapp()
  File "/Users/lhq/anaconda2/lib/python2.7/site-packages/gunicorn/app/wsgiapp.py", line 52, in load_wsgiapp
    return util.import_app(self.app_uri)
  File "/Users/lhq/anaconda2/lib/python2.7/site-packages/gunicorn/util.py", line 355, in import_app
    __import__(module)
ImportError: No module named run_inferencapp
[2017-04-02 22:33:21 +0800] [4304] [INFO] Worker exiting (pid: 4304)
[2017-04-02 22:33:28 +0800] [4310] [INFO] Starting gunicorn 19.3.0
[2017-04-02 22:33:28 +0800] [4310] [INFO] Listening at: http://127.0.0.1:8000 (4310)
[2017-04-02 22:33:28 +0800] [4310] [INFO] Using worker: sync
[2017-04-02 22:33:28 +0800] [4313] [INFO] Booting worker with pid: 4313
[2017-04-02 22:33:50 +0800] [4310] [INFO] Handling signal: int
[2017-04-02 22:33:50 +0800] [4313] [INFO] Worker exiting (pid: 4313)
[2017-04-02 22:33:50 +0800] [4310] [INFO] Shutting down: Master
[2017-04-02 22:34:03 +0800] [4337] [INFO] Starting gunicorn 19.3.0
[2017-04-02 22:34:03 +0800] [4337] [INFO] Listening at: http://127.0.0.1:8000 (4337)
[2017-04-02 22:34:03 +0800] [4337] [INFO] Using worker: sync
[2017-04-02 22:34:03 +0800] [4340] [INFO] Booting worker with pid: 4340
[2017-04-02 22:36:12 +0800] [4337] [CRITICAL] WORKER TIMEOUT (pid:4340)
[2017-04-02 22:36:12 +0800] [4340] [INFO] Worker exiting (pid: 4340)
[2017-04-02 22:36:12 +0800] [4362] [INFO] Booting worker with pid: 4362
[2017-04-02 22:38:25 +0800] [4337] [INFO] Handling signal: int
[2017-04-02 22:38:25 +0800] [4362] [INFO] Worker exiting (pid: 4362)
[2017-04-02 22:38:25 +0800] [4337] [INFO] Shutting down: Master
[2017-04-02 22:38:28 +0800] [4392] [INFO] Starting gunicorn 19.3.0
[2017-04-02 22:38:28 +0800] [4392] [INFO] Listening at: http://127.0.0.1:8000 (4392)
[2017-04-02 22:38:28 +0800] [4392] [INFO] Using worker: sync
[2017-04-02 22:38:28 +0800] [4395] [INFO] Booting worker with pid: 4395
[2017-04-02 22:39:30 +0800] [4392] [INFO] Handling signal: int
[2017-04-02 22:39:30 +0800] [4395] [INFO] Worker exiting (pid: 4395)
[2017-04-02 22:39:30 +0800] [4392] [INFO] Shutting down: Master
[2017-04-02 22:39:32 +0800] [4421] [INFO] Starting gunicorn 19.3.0
[2017-04-02 22:39:32 +0800] [4421] [INFO] Listening at: http://127.0.0.1:8000 (4421)
[2017-04-02 22:39:32 +0800] [4421] [INFO] Using worker: sync
[2017-04-02 22:39:32 +0800] [4424] [INFO] Booting worker with pid: 4424
[2017-04-02 22:39:54 +0800] [4424] [ERROR] Error handling request
Traceback (most recent call last):
  File "/Users/lhq/anaconda2/lib/python2.7/site-packages/gunicorn/workers/sync.py", line 130, in handle
    self.handle_request(listener, req, client, addr)
  File "/Users/lhq/anaconda2/lib/python2.7/site-packages/gunicorn/workers/sync.py", line 171, in handle_request
    respiter = self.wsgi(environ, resp.start_response)
  File "/Users/lhq/anaconda2/lib/python2.7/site-packages/flask/app.py", line 1836, in __call__
    return self.wsgi_app(environ, start_response)
  File "/Users/lhq/anaconda2/lib/python2.7/site-packages/flask/app.py", line 1820, in wsgi_app
    response = self.make_response(self.handle_exception(e))
  File "/Users/lhq/anaconda2/lib/python2.7/site-packages/flask/app.py", line 1403, in handle_exception
    reraise(exc_type, exc_value, tb)
  File "/Users/lhq/anaconda2/lib/python2.7/site-packages/flask/app.py", line 1817, in wsgi_app
    response = self.full_dispatch_request()
  File "/Users/lhq/anaconda2/lib/python2.7/site-packages/flask/app.py", line 1477, in full_dispatch_request
    rv = self.handle_user_exception(e)
  File "/Users/lhq/anaconda2/lib/python2.7/site-packages/flask/app.py", line 1381, in handle_user_exception
    reraise(exc_type, exc_value, tb)
  File "/Users/lhq/anaconda2/lib/python2.7/site-packages/flask/app.py", line 1475, in full_dispatch_request
    rv = self.dispatch_request()
  File "/Users/lhq/anaconda2/lib/python2.7/site-packages/flask/app.py", line 1461, in dispatch_request
    return self.view_functions[rule.endpoint](**req.view_args)
  File "/Users/lhq/Workspace/im2txt_api/im2txt/run_inference.py", line 191, in upload
    results = main(None)
  File "/Users/lhq/Workspace/im2txt_api/im2txt/run_inference.py", line 122, in main
    ans = str(ans.split('\"')[1])
UnicodeEncodeError: 'ascii' codec can't encode characters in position 0-13: ordinal not in range(128)
[2017-04-02 22:42:28 +0800] [4421] [INFO] Handling signal: int
[2017-04-02 22:42:28 +0800] [4424] [INFO] Worker exiting (pid: 4424)
[2017-04-02 22:42:28 +0800] [4421] [INFO] Shutting down: Master
[2017-04-02 22:42:29 +0800] [4476] [INFO] Starting gunicorn 19.3.0
[2017-04-02 22:42:29 +0800] [4476] [INFO] Listening at: http://127.0.0.1:8000 (4476)
[2017-04-02 22:42:29 +0800] [4476] [INFO] Using worker: sync
[2017-04-02 22:42:29 +0800] [4479] [INFO] Booting worker with pid: 4479
[2017-04-02 22:43:27 +0800] [4476] [INFO] Handling signal: int
[2017-04-02 22:43:27 +0800] [4479] [INFO] Worker exiting (pid: 4479)
[2017-04-02 22:43:27 +0800] [4476] [INFO] Shutting down: Master
[2017-04-02 22:43:30 +0800] [4502] [INFO] Starting gunicorn 19.3.0
[2017-04-02 22:43:30 +0800] [4502] [INFO] Listening at: http://127.0.0.1:8000 (4502)
[2017-04-02 22:43:30 +0800] [4502] [INFO] Using worker: sync
[2017-04-02 22:43:30 +0800] [4505] [INFO] Booting worker with pid: 4505
[2017-04-02 22:44:18 +0800] [4502] [CRITICAL] WORKER TIMEOUT (pid:4505)
[2017-04-02 22:44:18 +0800] [4505] [INFO] Worker exiting (pid: 4505)
[2017-04-02 22:44:18 +0800] [4520] [INFO] Booting worker with pid: 4520
[2017-04-02 22:45:43 +0800] [4502] [INFO] Handling signal: int
[2017-04-02 22:45:43 +0800] [4520] [INFO] Worker exiting (pid: 4520)
[2017-04-02 22:45:43 +0800] [4502] [INFO] Shutting down: Master
[2017-04-02 22:45:44 +0800] [4552] [INFO] Starting gunicorn 19.3.0
[2017-04-02 22:45:44 +0800] [4552] [INFO] Listening at: http://127.0.0.1:8000 (4552)
[2017-04-02 22:45:44 +0800] [4552] [INFO] Using worker: sync
[2017-04-02 22:45:44 +0800] [4555] [INFO] Booting worker with pid: 4555
[2017-04-02 22:46:48 +0800] [4552] [CRITICAL] WORKER TIMEOUT (pid:4555)
[2017-04-02 22:46:48 +0800] [4555] [INFO] Worker exiting (pid: 4555)
[2017-04-02 22:46:48 +0800] [4570] [INFO] Booting worker with pid: 4570
[2017-04-02 22:47:21 +0800] [4552] [CRITICAL] WORKER TIMEOUT (pid:4570)
[2017-04-02 22:47:21 +0800] [4570] [INFO] Worker exiting (pid: 4570)
[2017-04-02 22:47:21 +0800] [4581] [INFO] Booting worker with pid: 4581
[2017-04-02 22:54:57 +0800] [4552] [INFO] Handling signal: int
[2017-04-02 22:54:57 +0800] [4581] [INFO] Worker exiting (pid: 4581)
[2017-04-02 22:54:57 +0800] [4552] [INFO] Shutting down: Master
[2017-04-02 22:55:01 +0800] [4703] [INFO] Starting gunicorn 19.3.0
[2017-04-02 22:55:01 +0800] [4703] [INFO] Listening at: http://127.0.0.1:8000 (4703)
[2017-04-02 22:55:01 +0800] [4703] [INFO] Using worker: sync
[2017-04-02 22:55:01 +0800] [4706] [INFO] Booting worker with pid: 4706
[2017-04-02 22:56:12 +0800] [4703] [CRITICAL] WORKER TIMEOUT (pid:4706)
[2017-04-02 22:56:12 +0800] [4706] [INFO] Worker exiting (pid: 4706)
[2017-04-02 22:56:13 +0800] [4725] [INFO] Booting worker with pid: 4725
[2017-04-02 22:56:30 +0800] [4703] [INFO] Handling signal: int
[2017-04-02 22:56:30 +0800] [4725] [INFO] Worker exiting (pid: 4725)
[2017-04-02 22:56:30 +0800] [4703] [INFO] Shutting down: Master
[2017-04-02 22:56:31 +0800] [4744] [INFO] Starting gunicorn 19.3.0
[2017-04-02 22:56:31 +0800] [4744] [INFO] Listening at: http://127.0.0.1:8000 (4744)
[2017-04-02 22:56:31 +0800] [4744] [INFO] Using worker: sync
[2017-04-02 22:56:31 +0800] [4747] [INFO] Booting worker with pid: 4747
[2017-04-02 23:00:34 +0800] [4744] [INFO] Handling signal: int
[2017-04-02 23:00:34 +0800] [4747] [INFO] Worker exiting (pid: 4747)
[2017-04-02 23:00:34 +0800] [4744] [INFO] Shutting down: Master
[2017-04-02 23:00:36 +0800] [4824] [INFO] Starting gunicorn 19.3.0
[2017-04-02 23:00:36 +0800] [4824] [INFO] Listening at: http://127.0.0.1:8000 (4824)
[2017-04-02 23:00:36 +0800] [4824] [INFO] Using worker: sync
[2017-04-02 23:00:36 +0800] [4827] [INFO] Booting worker with pid: 4827
[2017-04-02 23:01:21 +0800] [4824] [CRITICAL] WORKER TIMEOUT (pid:4827)
[2017-04-02 23:01:21 +0800] [4827] [INFO] Worker exiting (pid: 4827)
[2017-04-02 23:01:21 +0800] [4838] [INFO] Booting worker with pid: 4838
[2017-04-02 23:03:46 +0800] [4824] [INFO] Handling signal: int
[2017-04-02 23:03:46 +0800] [4838] [INFO] Worker exiting (pid: 4838)
[2017-04-02 23:03:46 +0800] [4824] [INFO] Shutting down: Master
[2017-04-02 23:03:47 +0800] [4903] [INFO] Starting gunicorn 19.3.0
[2017-04-02 23:03:47 +0800] [4903] [INFO] Listening at: http://127.0.0.1:8000 (4903)
[2017-04-02 23:03:47 +0800] [4903] [INFO] Using worker: sync
[2017-04-02 23:03:47 +0800] [4907] [INFO] Booting worker with pid: 4907
[2017-04-02 23:05:49 +0800] [4903] [INFO] Handling signal: int
[2017-04-02 23:05:49 +0800] [4907] [INFO] Worker exiting (pid: 4907)
[2017-04-02 23:05:49 +0800] [4903] [INFO] Shutting down: Master
[2017-04-02 23:05:50 +0800] [4943] [INFO] Starting gunicorn 19.3.0
[2017-04-02 23:05:50 +0800] [4943] [INFO] Listening at: http://127.0.0.1:8000 (4943)
[2017-04-02 23:05:50 +0800] [4943] [INFO] Using worker: sync
[2017-04-02 23:05:50 +0800] [4946] [INFO] Booting worker with pid: 4946
[2017-04-02 23:06:09 +0800] [4946] [ERROR] Error handling request
Traceback (most recent call last):
  File "/Users/lhq/anaconda2/lib/python2.7/site-packages/gunicorn/workers/sync.py", line 130, in handle
    self.handle_request(listener, req, client, addr)
  File "/Users/lhq/anaconda2/lib/python2.7/site-packages/gunicorn/workers/sync.py", line 171, in handle_request
    respiter = self.wsgi(environ, resp.start_response)
  File "/Users/lhq/anaconda2/lib/python2.7/site-packages/flask/app.py", line 1836, in __call__
    return self.wsgi_app(environ, start_response)
  File "/Users/lhq/anaconda2/lib/python2.7/site-packages/flask/app.py", line 1820, in wsgi_app
    response = self.make_response(self.handle_exception(e))
  File "/Users/lhq/anaconda2/lib/python2.7/site-packages/flask/app.py", line 1403, in handle_exception
    reraise(exc_type, exc_value, tb)
  File "/Users/lhq/anaconda2/lib/python2.7/site-packages/flask/app.py", line 1817, in wsgi_app
    response = self.full_dispatch_request()
  File "/Users/lhq/anaconda2/lib/python2.7/site-packages/flask/app.py", line 1477, in full_dispatch_request
    rv = self.handle_user_exception(e)
  File "/Users/lhq/anaconda2/lib/python2.7/site-packages/flask/app.py", line 1381, in handle_user_exception
    reraise(exc_type, exc_value, tb)
  File "/Users/lhq/anaconda2/lib/python2.7/site-packages/flask/app.py", line 1475, in full_dispatch_request
    rv = self.dispatch_request()
  File "/Users/lhq/anaconda2/lib/python2.7/site-packages/flask/app.py", line 1461, in dispatch_request
    return self.view_functions[rule.endpoint](**req.view_args)
  File "/Users/lhq/Workspace/im2txt_api/im2txt/run_inference.py", line 193, in upload
    return render_template("result.html", {"results":results, "path":path})
TypeError: render_template() takes exactly 1 argument (2 given)
[2017-04-02 23:38:46 +0800] [4946] [ERROR] Error handling request
Traceback (most recent call last):
  File "/Users/lhq/anaconda2/lib/python2.7/site-packages/gunicorn/workers/sync.py", line 130, in handle
    self.handle_request(listener, req, client, addr)
  File "/Users/lhq/anaconda2/lib/python2.7/site-packages/gunicorn/workers/sync.py", line 171, in handle_request
    respiter = self.wsgi(environ, resp.start_response)
  File "/Users/lhq/anaconda2/lib/python2.7/site-packages/flask/app.py", line 1836, in __call__
    return self.wsgi_app(environ, start_response)
  File "/Users/lhq/anaconda2/lib/python2.7/site-packages/flask/app.py", line 1820, in wsgi_app
    response = self.make_response(self.handle_exception(e))
  File "/Users/lhq/anaconda2/lib/python2.7/site-packages/flask/app.py", line 1403, in handle_exception
    reraise(exc_type, exc_value, tb)
  File "/Users/lhq/anaconda2/lib/python2.7/site-packages/flask/app.py", line 1817, in wsgi_app
    response = self.full_dispatch_request()
  File "/Users/lhq/anaconda2/lib/python2.7/site-packages/flask/app.py", line 1477, in full_dispatch_request
    rv = self.handle_user_exception(e)
  File "/Users/lhq/anaconda2/lib/python2.7/site-packages/flask/app.py", line 1381, in handle_user_exception
    reraise(exc_type, exc_value, tb)
  File "/Users/lhq/anaconda2/lib/python2.7/site-packages/flask/app.py", line 1475, in full_dispatch_request
    rv = self.dispatch_request()
  File "/Users/lhq/anaconda2/lib/python2.7/site-packages/flask/app.py", line 1461, in dispatch_request
    return self.view_functions[rule.endpoint](**req.view_args)
  File "/Users/lhq/Workspace/im2txt_api/im2txt/run_inference.py", line 193, in upload
    return render_template("result.html", data = {"results":results, "path":path})
TypeError: render_template() takes exactly 1 argument (2 given)
[2017-04-02 23:38:50 +0800] [4943] [INFO] Handling signal: int
[2017-04-02 23:38:50 +0800] [4946] [INFO] Worker exiting (pid: 4946)
[2017-04-02 23:38:50 +0800] [4943] [INFO] Shutting down: Master
[2017-04-02 23:39:39 +0800] [5016] [INFO] Starting gunicorn 19.3.0
[2017-04-02 23:39:39 +0800] [5016] [INFO] Listening at: http://127.0.0.1:8000 (5016)
[2017-04-02 23:39:39 +0800] [5016] [INFO] Using worker: sync
[2017-04-02 23:39:39 +0800] [5019] [INFO] Booting worker with pid: 5019
[2017-04-02 23:40:49 +0800] [5016] [INFO] Handling signal: int
[2017-04-02 23:40:49 +0800] [5019] [INFO] Worker exiting (pid: 5019)
[2017-04-02 23:40:50 +0800] [5016] [INFO] Shutting down: Master
